Workbook
Name Slicer_inventory_status: #N/A
Name Slicer_item_level: #N/A
Name Slicer_order_status: #N/A

Sheet Dashboard
H1: MRP & Production Planning Dashboard | W1: Last Updated:
W2: =NOW() -> 46225.546
D5: Total Customer Demand | G5: Total Planned Production | J5: Total Planned Purchase | M5: Low Stock Items | P5: Out of Stock Items | S5: Inventory Available
D8: =SUM(tblCustomerOrders[order_quantity]) -> 58 | G8: =SUM(MRP!H:H) -> 590 | J8: =SUM(MRP!I:I) -> 13373 | M8: =COUNTIF(tblInventory[inventory_status],"Low Stock") -> 14 | P8: =COUNTIF(tblInventory[inventory_status],"Out of Stock") -> 7 | S8: =SUM(tblInventory[available_quantity]) -> 339
S17: Row Labels | T17: Count of item_id
C18: Production | D18: =SUM(MRP!H:H) -> 590 | H18: Row Labels | I18: Count of item_id | M18: Row Labels | N18: Count of customer_order_id | S18: Healthy | T18: 64
C19: Purchase | D19: =SUM(MRP!I:I) -> 13373 | H19: 0 | I19: 1 | M19: Cancelled | N19: 2 | S19: Low Stock | T19: 14
H20: 1 | I20: 4 | M20: Completed | N20: 1 | S20: Out of Stock | T20: 7
H21: 2 | I21: 23 | M21: Pending | N21: 5 | S21: Grand Total | T21: 85
H22: 3 | I22: 57 | M22: Released | N22: 3
H23: Grand Total | I23: 85 | M23: Grand Total | N23: 11

Sheet Items
A1: item_id | B1: item_name | C1: item_level | D1: item_category | E1: procurement_type | F1: supplier_id | G1: unit_of_measure | H1: is_active
A2: 1 | B2: Industrial Centrifugal Water Pump | C2: 0 | D2: Finished Product | E2: Manufactured | F2: NULL | G2: EA | H2: TRUE
A3: 2 | B3: Pump Assembly | C3: 1 | D3: Assembly | E3: Manufactured | F3: NULL | G3: EA | H3: TRUE
A4: 3 | B4: Electric Motor Assembly | C4: 1 | D4: Assembly | E4: Manufactured | F4: NULL | G4: EA | H4: TRUE
A5: 4 | B5: Base Frame Assembly | C5: 1 | D5: Assembly | E5: Manufactured | F5: NULL | G5: EA | H5: TRUE
A6: 5 | B6: Packaging Assembly | C6: 1 | D6: Assembly | E6: Manufactured | F6: NULL | G6: EA | H6: TRUE
A7: 6 | B7: Casing Assembly | C7: 2 | D7: Assembly | E7: Manufactured | F7: NULL | G7: EA | H7: TRUE
A8: 7 | B8: Rotating Assembly | C8: 2 | D8: Assembly | E8: Manufactured | F8: NULL | G8: EA | H8: TRUE
A9: 8 | B9: Mechanical Seal Assembly | C9: 2 | D9: Assembly | E9: Manufactured | F9: NULL | G9: EA | H9: TRUE
A10: 9 | B10: Suction Flange | C10: 2 | D10: Component | E10: Purchased | F10: 3 | G10: EA | H10: TRUE
A11: 10 | B11: Discharge Flange | C11: 2 | D11: Component | E11: Purchased | F11: 3 | G11: EA | H11: TRUE
A12: 11 | B12: Motor Housing Assembly | C12: 2 | D12: Assembly | E12: Manufactured | F12: NULL | G12: EA | H12: TRUE
A13: 12 | B13: Rotor Assembly | C13: 2 | D13: Assembly | E13: Manufactured | F13: NULL | G13: EA | H13: TRUE
A14: 13 | B14: Stator Assembly | C14: 2 | D14: Assembly | E14: Manufactured | F14: NULL | G14: EA | H14: TRUE
A15: 14 | B15: Cooling Fan Assembly | C15: 2 | D15: Assembly | E15: Manufactured | F15: NULL | G15: EA | H15: TRUE
A16: 15 | B16: Terminal Box Assembly | C16: 2 | D16: Assembly | E16: Manufactured | F16: NULL | G16: EA | H16: TRUE
A17: 16 | B17: Base Plate | C17: 2 | D17: Component | E17: Purchased | F17: 4 | G17: EA | H17: TRUE
A18: 17 | B18: Mounting Feet | C18: 2 | D18: Component | E18: Purchased | F18: 4 | G18: EA | H18: TRUE
A19: 18 | B19: Coupling Guard | C19: 2 | D19: Component | E19: Purchased | F19: 4 | G19: EA | H19: TRUE
A20: 19 | B20: Anti Vibration Pads | C20: 2 | D20: Component | E20: Purchased | F20: 2 | G20: EA | H20: TRUE
A21: 20 | B21: Anchor Bolts | C21: 2 | D21: Component | E21: Purchased | F21: 8 | G21: EA | H21: TRUE
A22: 21 | B22: Anchor Nuts | C22: 2 | D22: Component | E22: Purchased | F22: 8 | G22: EA | H22: TRUE
A23: 22 | B23: Flat Washers | C23: 2 | D23: Component | E23: Purchased | F23: 8 | G23: EA | H23: TRUE
A24: 23 | B24: Carton Box | C24: 2 | D24: Component | E24: Purchased | F24: 9 | G24: EA | H24: TRUE
A25: 24 | B25: Foam Inserts | C25: 2 | D25: Component | E25: Purchased | F25: 9 | G25: EA | H25: TRUE
A26: 25 | B26: Plastic Bag | C26: 2 | D26: Component | E26: Purchased | F26: 9 | G26: EA | H26: TRUE
A27: 26 | B27: User Manual | C27: 2 | D27: Component | E27: Purchased | F27: 9 | G27: EA | H27: TRUE
A28: 27 | B28: Warranty Card | C28: 2 | D28: Component | E28: Purchased | F28: 9 | G28: EA | H28: TRUE
... A86: 85 | B86: Cable Clamp | C86: 3 | D86: Component | E86: Purchased | F86: 10 | G86: EA | H86: TRUE

Sheet BOM
A1: bom_id | B1: parent_item_id | C1: child_item_id | D1: quantity_required | E1: sequence_no
A2: 1 | B2: 1 | C2: 2 | D2: 1 | E2: 1
A3: 2 | B3: 1 | C3: 3 | D3: 1 | E3: 2
A4: 3 | B4: 1 | C4: 4 | D4: 1 | E4: 3
A5: 4 | B5: 1 | C5: 5 | D5: 1 | E5: 4
A6: 5 | B6: 2 | C6: 6 | D6: 1 | E6: 1
A7: 6 | B7: 2 | C7: 7 | D7: 1 | E7: 2
A8: 7 | B8: 2 | C8: 8 | D8: 1 | E8: 3
A9: 8 | B9: 2 | C9: 9 | D9: 1 | E9: 4
A10: 9 | B10: 2 | C10: 10 | D10: 1 | E10: 5
A11: 10 | B11: 3 | C11: 11 | D11: 1 | E11: 1
A12: 11 | B12: 3 | C12: 12 | D12: 1 | E12: 2
A13: 12 | B13: 3 | C13: 13 | D13: 1 | E13: 3
... A89: 88 | B89: 15 | C89: 85 | D89: 2 | E89: 7

Sheet Inventory
A1: item_id | B1: quantity_on_hand | C1: allocated_quantity | D1: available_quantity | E1: last_updated | F1: inventory_status | G1: item_name
A2: 1 | B2: 0 | C2: 0 | D2: 0 | E2: 46224.414 | F2: =IF(D2=0,"Out of Stock",IF(D2<3,"Low Stock","Healthy")) -> Out of Stock | G2: =_xlfn.XLOOKUP(A2,tblItems[item_id],tblItems[item_name]) -> Industrial Centrifugal Water Pump
A3: 2 | B3: 0 | C3: 0 | D3: 0 | E3: 46224.414 | F3: =IF(D3=0,"Out of Stock",IF(D3<3,"Low Stock","Healthy")) -> Out of Stock | G3: =_xlfn.XLOOKUP(A3,tblItems[item_id],tblItems[item_name]) -> Pump Assembly
A4: 3 | B4: 0 | C4: 0 | D4: 0 | E4: 46224.414 | F4: =IF(D4=0,"Out of Stock",IF(D4<3,"Low Stock","Healthy")) -> Out of Stock | G4: =_xlfn.XLOOKUP(A4,tblItems[item_id],tblItems[item_name]) -> Electric Motor Assembly
A5: 4 | B5: 0 | C5: 0 | D5: 0 | E5: 46224.414 | F5: =IF(D5=0,"Out of Stock",IF(D5<3,"Low Stock","Healthy")) -> Out of Stock | G5: =_xlfn.XLOOKUP(A5,tblItems[item_id],tblItems[item_name]) -> Base Frame Assembly
A6: 5 | B6: 0 | C6: 0 | D6: 0 | E6: 46224.414 | F6: =IF(D6=0,"Out of Stock",IF(D6<3,"Low Stock","Healthy")) -> Out of Stock | G6: =_xlfn.XLOOKUP(A6,tblItems[item_id],tblItems[item_name]) -> Packaging Assembly
A7: 6 | B7: 1 | C7: 0 | D7: 1 | E7: 46224.414 | F7: =IF(D7=0,"Out of Stock",IF(D7<3,"Low Stock","Healthy")) -> Low Stock | G7: =_xlfn.XLOOKUP(A7,tblItems[item_id],tblItems[item_name]) -> Casing Assembly
A8: 7 | B8: 0 | C8: 0 | D8: 0 | E8: 46224.414 | F8: =IF(D8=0,"Out of Stock",IF(D8<3,"Low Stock","Healthy")) -> Out of Stock | G8: =_xlfn.XLOOKUP(A8,tblItems[item_id],tblItems[item_name]) -> Rotating Assembly
A9: 8 | B9: 2 | C9: 0 | D9: 2 | E9: 46224.414 | F9: =IF(D9=0,"Out of Stock",IF(D9<3,"Low Stock","Healthy")) -> Low Stock | G9: =_xlfn.XLOOKUP(A9,tblItems[item_id],tblItems[item_name]) -> Mechanical Seal Assembly
A10: 9 | B10: 5 | C10: 1 | D10: 4 | E10: 46224.414 | F10: =IF(D10=0,"Out of Stock",IF(D10<3,"Low Stock","Healthy")) -> Healthy | G10: =_xlfn.XLOOKUP(A10,tblItems[item_id],tblItems[item_name]) -> Suction Flange
A11: 10 | B11: 4 | C11: 1 | D11: 3 | E11: 46224.414 | F11: =IF(D11=0,"Out of Stock",IF(D11<3,"Low Stock","Healthy")) -> Healthy | G11: =_xlfn.XLOOKUP(A11,tblItems[item_id],tblItems[item_name]) -> Discharge Flange
A12: 11 | B12: 1 | C12: 0 | D12: 1 | E12: 46224.414 | F12: =IF(D12=0,"Out of Stock",IF(D12<3,"Low Stock","Healthy")) -> Low Stock | G12: =_xlfn.XLOOKUP(A12,tblItems[item_id],tblItems[item_name]) -> Motor Housing Assembly
A13: 12 | B13: 0 | C13: 0 | D13: 0 | E13: 46224.414 | F13: =IF(D13=0,"Out of Stock",IF(D13<3,"Low Stock","Healthy")) -> Out of Stock | G13: =_xlfn.XLOOKUP(A13,tblItems[item_id],tblItems[item_name]) -> Rotor Assembly
... A86: 85 | B86: 5 | C86: 1 | D86: 4 | E86: 46224.414 | F86: =IF(D86=0,"Out of Stock",IF(D86<3,"Low Stock","Healthy")) -> Healthy | G86: =_xlfn.XLOOKUP(A86,tblItems[item_id],tblItems[item_name]) -> Cable Clamp

Sheet Customer Orders
A1: customer_order_id | B1: customer_name | C1: item_id | D1: order_quantity | E1: order_date | F1: due_date | G1: order_status
A2: 1 | B2: ABC Industries | C2: 1 | D2: 5 | E2: 46235 | F2: 46244 | G2: Pending
A3: 2 | B3: Delta Manufacturing | C3: 1 | D3: 3 | E3: 46236 | F3: 46246 | G3: Released
A4: 3 | B4: HydroTech Solutions | C4: 1 | D4: 8 | E4: 46237 | F4: 46249 | G4: Pending
A5: 4 | B5: Prime Engineering | C5: 1 | D5: 2 | E5: 46239 | F5: 46247 | G5: Completed
A6: 5 | B6: Apex Pumps Ltd. | C6: 1 | D6: 6 | E6: 46240 | F6: 46252 | G6: Pending
A7: 6 | B7: Global Water Systems | C7: 1 | D7: 4 | E7: 46242 | F7: 46251 | G7: Released
A8: 7 | B8: Vertex Engineering | C8: 1 | D8: 7 | E8: 46243 | F8: 46254 | G8: Pending
A9: 8 | B9: BlueRiver Industries | C9: 1 | D9: 3 | E9: 46244 | F9: 46253 | G9: Cancelled
A10: 9 | B10: Metro Process Equipments | C10: 1 | D10: 9 | E10: 46245 | F10: 46259 | G10: Pending
A11: 10 | B11: Nova Industrial Works | C11: 1 | D11: 4 | E11: 46246 | F11: 46256 | G11: Released
A12: 11 | B12: Hela Innovations | C12: 1 | D12: 7 | E12: 46249 | F12: 46255 | G12: Cancelled

Sheet Suppliers
A1: supplier_id | B1: supplier_name | C1: city | D1: country | E1: email | F1: phone | G1: is_active
A2: 1 | B2: SKF India Ltd. | C2: Pune | D2: India | E2: contact@skfindia.com | F2: =91-20-40010001 -> -40009930 | G2: TRUE
A3: 2 | B3: Trelleborg Sealing Solutions | C3: Bengaluru | D3: India | E3: sales@trelleborg.com | F3: =91-80-40010002 -> -40009991 | G3: TRUE
A4: 3 | B4: L&T Valves | C4: Chennai | D4: India | E4: info@ltvalves.com | F4: =91-44-40010003 -> -40009956 | G4: TRUE
A5: 4 | B5: Tata Steel Processing | C5: Jamshedpur | D5: India | E5: support@tatasteel.com | F5: =91-657-4001004 -> -4001570 | G5: TRUE
A6: 5 | B6: Hindalco Industries | C6: Mumbai | D6: India | E6: sales@hindalco.com | F6: =91-22-40010005 -> -40009936 | G6: TRUE
A7: 6 | B7: RR Kabel | C7: Vadodara | D7: India | E7: contact@rrkabel.com | F7: =91-265-40010006 -> -40010180 | G7: TRUE
A8: 7 | B8: Saint-Gobain India | C8: Chennai | D8: India | E8: info@saint-gobain.com | F8: =91-44-40010007 -> -40009960 | G8: TRUE
A9: 8 | B9: Fasteners India Pvt. Ltd. | C9: Ludhiana | D9: India | E9: sales@fastenersindia.com | F9: =91-161-40010008 -> -40010078 | G9: TRUE
A10: 9 | B10: Packwell Packaging | C10: Noida | D10: India | E10: info@packwell.com | F10: =91-120-40010009 -> -40010038 | G10: TRUE
A11: 10 | B11: C&S Electric | C11: Delhi | D11: India | E11: support@cselectric.com | F11: =91-11-40010010 -> -40009930 | G11: TRUE

Sheet BOM Explosion
A1: Parent Item ID | B1: Child Item ID | C1: BOM Qty | D1: Parent Net Requirement | E1: Child Gross Requirement | F1: Level
A2: {=tblBOM[parent_item_id]} -> 1 | B2: {=tblBOM[child_item_id]} -> 2 | C2: {=tblBOM[quantity_required]} -> 1 | D2: {=_xlfn.XLOOKUP(_xlfn.ANCHORARRAY(A2), MRP!A:A, MRP!G:G)} -> 46 | E2: {=_xlfn.ANCHORARRAY(C2)*_xlfn.ANCHORARRAY(D2)} -> 46 | F2: {=_xlfn.XLOOKUP(_xlfn.ANCHORARRAY(B2), tblItems[item_id], tblItems[item_level])} -> 1
A3: 1 | B3: 3 | C3: 1 | D3: 46 | E3: 46 | F3: 1
A4: 1 | B4: 4 | C4: 1 | D4: 46 | E4: 46 | F4: 1
A5: 1 | B5: 5 | C5: 1 | D5: 46 | E5: 46 | F5: 1
A6: 2 | B6: 6 | C6: 1 | D6: 46 | E6: 46 | F6: 2
A7: 2 | B7: 7 | C7: 1 | D7: 46 | E7: 46 | F7: 2
A8: 2 | B8: 8 | C8: 1 | D8: 46 | E8: 46 | F8: 2
A9: 2 | B9: 9 | C9: 1 | D9: 46 | E9: 46 | F9: 2
A10: 2 | B10: 10 | C10: 1 | D10: 46 | E10: 46 | F10: 2
A11: 3 | B11: 11 | C11: 1 | D11: 46 | E11: 46 | F11: 2
A12: 3 | B12: 12 | C12: 1 | D12: 46 | E12: 46 | F12: 2
A13: 3 | B13: 13 | C13: 1 | D13: 46 | E13: 46 | F13: 2
A14: 3 | B14: 14 | C14: 1 | D14: 46 | E14: 46 | F14: 2
... A89: 15 | B89: 85 | C89: 2 | D89: 45 | E89: 90 | F89: 3

Sheet MRP
A1: item_id | B1: item_name | C1: item_level | D1: procurement_type | E1: available_inventory | F1: gross_requirement | G1: net_requirement | H1: planned_production | I1: planned_purchase
A2: {=tblItems[item_id]} -> 1 | B2: {=_xlfn.XLOOKUP(_xlfn.ANCHORARRAY(A2), tblItems[item_id], tblItems[item_name])} -> Industrial Centrifugal Water Pump | C2: {=_xlfn.XLOOKUP(_xlfn.ANCHORARRAY(A2), tblItems[item_id], tblItems[item_level])} -> 0 | D2: {=_xlfn.XLOOKUP(_xlfn.ANCHORARRAY(A2), tblItems[item_id], tblItems[procurement_type])} -> Manufactured | E2: {=_xlfn.XLOOKUP(_xlfn.ANCHORARRAY(A2), tblInventory[item_id], tblInventory[available_quantity])} -> 0 | F2: {=SUM(SUMIFS(tblCustomerOrders[order_quantity],tblCustomerOrders[item_id],1,tblCustomerOrders[order_status],{"Pending","Released"}))} -> 46 | G2: =MAX(F2-E2,0) -> 46 | H2: =IF(D2="Manufactured",G2,0) -> 46 | I2: =IF(D2="Purchased",G2,0) -> 0
A3: 2 | B3: Pump Assembly | C3: 1 | D3: Manufactured | E3: 0 | F3: =G2*1 -> 46 | G3: =MAX(F3-E3,0) -> 46 | H3: =IF(D3="Manufactured",G3,0) -> 46 | I3: =IF(D3="Purchased",G3,0) -> 0
A4: 3 | B4: Electric Motor Assembly | C4: 1 | D4: Manufactured | E4: 0 | F4: =G2*1 -> 46 | G4: =MAX(F4-E4,0) -> 46 | H4: =IF(D4="Manufactured",G4,0) -> 46 | I4: =IF(D4="Purchased",G4,0) -> 0
A5: 4 | B5: Base Frame Assembly | C5: 1 | D5: Manufactured | E5: 0 | F5: =G2*1 -> 46 | G5: =MAX(F5-E5,0) -> 46 | H5: =IF(D5="Manufactured",G5,0) -> 46 | I5: =IF(D5="Purchased",G5,0) -> 0
A6: 5 | B6: Packaging Assembly | C6: 1 | D6: Manufactured | E6: 0 | F6: =G2*1 -> 46 | G6: =MAX(F6-E6,0) -> 46 | H6: =IF(D6="Manufactured",G6,0) -> 46 | I6: =IF(D6="Purchased",G6,0) -> 0
A7: 6 | B7: Casing Assembly | C7: 2 | D7: Manufactured | E7: 1 | F7: =G3 -> 46 | G7: =MAX(F7-E7,0) -> 45 | H7: =IF(D7="Manufactured",G7,0) -> 45 | I7: =IF(D7="Purchased",G7,0) -> 0
A8: 7 | B8: Rotating Assembly | C8: 2 | D8: Manufactured | E8: 0 | F8: =G3 -> 46 | G8: =MAX(F8-E8,0) -> 46 | H8: =IF(D8="Manufactured",G8,0) -> 46 | I8: =IF(D8="Purchased",G8,0) -> 0
A9: 8 | B9: Mechanical Seal Assembly | C9: 2 | D9: Manufactured | E9: 2 | F9: =G3 -> 46 | G9: =MAX(F9-E9,0) -> 44 | H9: =IF(D9="Manufactured",G9,0) -> 44 | I9: =IF(D9="Purchased",G9,0) -> 0
A10: 9 | B10: Suction Flange | C10: 2 | D10: Purchased | E10: 4 | F10: =G3 -> 46 | G10: =MAX(F10-E10,0) -> 42 | H10: =IF(D10="Manufactured",G10,0) -> 0 | I10: =IF(D10="Purchased",G10,0) -> 42
A11: 10 | B11: Discharge Flange | C11: 2 | D11: Purchased | E11: 3 | F11: =G3 -> 46 | G11: =MAX(F11-E11,0) -> 43 | H11: =IF(D11="Manufactured",G11,0) -> 0 | I11: =IF(D11="Purchased",G11,0) -> 43
A12: 11 | B12: Motor Housing Assembly | C12: 2 | D12: Manufactured | E12: 1 | F12: =G4 -> 46 | G12: =MAX(F12-E12,0) -> 45 | H12: =IF(D12="Manufactured",G12,0) -> 45 | I12: =IF(D12="Purchased",G12,0) -> 0
A13: 12 | B13: Rotor Assembly | C13: 2 | D13: Manufactured | E13: 0 | F13: =G3 -> 46 | G13: =MAX(F13-E13,0) -> 46 | H13: =IF(D13="Manufactured",G13,0) -> 46 | I13: =IF(D13="Purchased",G13,0) -> 0
A14: 13 | B14: Stator Assembly | C14: 2 | D14: Manufactured | E14: 1 | F14: =G3 -> 46 | G14: =MAX(F14-E14,0) -> 45 | H14: =IF(D14="Manufactured",G14,0) -> 45 | I14: =IF(D14="Purchased",G14,0) -> 0
A15: 14 | B15: Cooling Fan Assembly | C15: 2 | D15: Manufactured | E15: 2 | F15: =G3 -> 46 | G15: =MAX(F15-E15,0) -> 44 | H15: =IF(D15="Manufactured",G15,0) -> 44 | I15: =IF(D15="Purchased",G15,0) -> 0
A16: 15 | B16: Terminal Box Assembly | C16: 2 | D16: Manufactured | E16: 1 | F16: =G3 -> 46 | G16: =MAX(F16-E16,0) -> 45 | H16: =IF(D16="Manufactured",G16,0) -> 45 | I16: =IF(D16="Purchased",G16,0) -> 0
A17: 16 | B17: Base Plate | C17: 2 | D17: Purchased | E17: 4 | F17: =G5 -> 46 | G17: =MAX(F17-E17,0) -> 42 | H17: =IF(D17="Manufactured",G17,0) -> 0 | I17: =IF(D17="Purchased",G17,0) -> 42
A18: 17 | B18: Mounting Feet | C18: 2 | D18: Purchased | E18: 5 | F18: =G5*2 -> 92 | G18: =MAX(F18-E18,0) -> 87 | H18: =IF(D18="Manufactured",G18,0) -> 0 | I18: =IF(D18="Purchased",G18,0) -> 87
A19: 18 | B19: Coupling Guard | C19: 2 | D19: Purchased | E19: 3 | F19: =G5 -> 46 | G19: =MAX(F19-E19,0) -> 43 | H19: =IF(D19="Manufactured",G19,0) -> 0 | I19: =IF(D19="Purchased",G19,0) -> 43
A20: 19 | B20: Anti Vibration Pads | C20: 2 | D20: Purchased | E20: 4 | F20: =G5*4 -> 184 | G20: =MAX(F20-E20,0) -> 180 | H20: =IF(D20="Manufactured",G20,0) -> 0 | I20: =IF(D20="Purchased",G20,0) -> 180
A21: 20 | B21: Anchor Bolts | C21: 2 | D21: Purchased | E21: 8 | F21: =G5*4 -> 184 | G21: =MAX(F21-E21,0) -> 176 | H21: =IF(D21="Manufactured",G21,0) -> 0 | I21: =IF(D21="Purchased",G21,0) -> 176
A22: 21 | B22: Anchor Nuts | C22: 2 | D22: Purchased | E22: 8 | F22: =G5*4 -> 184 | G22: =MAX(F22-E22,0) -> 176 | H22: =IF(D22="Manufactured",G22,0) -> 0 | I22: =IF(D22="Purchased",G22,0) -> 176
A23: 22 | B23: Flat Washers | C23: 2 | D23: Purchased | E23: 8 | F23: =G5*4 -> 184 | G23: =MAX(F23-E23,0) -> 176 | H23: =IF(D23="Manufactured",G23,0) -> 0 | I23: =IF(D23="Purchased",G23,0) -> 176
A24: 23 | B24: Carton Box | C24: 2 | D24: Purchased | E24: 4 | F24: =G6 -> 46 | G24: =MAX(F24-E24,0) -> 42 | H24: =IF(D24="Manufactured",G24,0) -> 0 | I24: =IF(D24="Purchased",G24,0) -> 42
A25: 24 | B25: Foam Inserts | C25: 2 | D25: Purchased | E25: 5 | F25: =G6*2 -> 92 | G25: =MAX(F25-E25,0) -> 87 | H25: =IF(D25="Manufactured",G25,0) -> 0 | I25: =IF(D25="Purchased",G25,0) -> 87
A26: 25 | B26: Plastic Bag | C26: 2 | D26: Purchased | E26: 4 | F26: =G6 -> 46 | G26: =MAX(F26-E26,0) -> 42 | H26: =IF(D26="Manufactured",G26,0) -> 0 | I26: =IF(D26="Purchased",G26,0) -> 42
A27: 26 | B27: User Manual | C27: 2 | D27: Purchased | E27: 8 | F27: =G6 -> 46 | G27: =MAX(F27-E27,0) -> 38 | H27: =IF(D27="Manufactured",G27,0) -> 0 | I27: =IF(D27="Purchased",G27,0) -> 38
A28: 27 | B28: Warranty Card | C28: 2 | D28: Purchased | E28: 8 | F28: =G6 -> 46 | G28: =MAX(F28-E28,0) -> 38 | H28: =IF(D28="Manufactured",G28,0) -> 0 | I28: =IF(D28="Purchased",G28,0) -> 38
A29: 28 | B29: Product Label | C29: 2 | D29: Purchased | E29: 8 | F29: =G6*2 -> 92 | G29: =MAX(F29-E29,0) -> 84 | H29: =IF(D29="Manufactured",G29,0) -> 0 | I29: =IF(D29="Purchased",G29,0) -> 84
A30: 29 | B30: Pump Casing | C30: 3 | D30: Purchased | E30: 3 | F30: =G7 -> 45 | G30: =MAX(F30-E30,0) -> 42 | H30: =IF(D30="Manufactured",G30,0) -> 0 | I30: =IF(D30="Purchased",G30,0) -> 42
A31: 30 | B31: Casing Cover | C31: 3 | D31: Purchased | E31: 2 | F31: =G7 -> 45 | G31: =MAX(F31-E31,0) -> 43 | H31: =IF(D31="Manufactured",G31,0) -> 0 | I31: =IF(D31="Purchased",G31,0) -> 43
A32: 31 | B32: Wear Ring | C32: 3 | D32: Purchased | E32: 3 | F32: =G7*2 -> 90 | G32: =MAX(F32-E32,0) -> 87 | H32: =IF(D32="Manufactured",G32,0) -> 0 | I32: =IF(D32="Purchased",G32,0) -> 87
A33: 32 | B33: Casing Gasket | C33: 3 | D33: Purchased | E33: 5 | F33: =G7 -> 45 | G33: =MAX(F33-E33,0) -> 40 | H33: =IF(D33="Manufactured",G33,0) -> 0 | I33: =IF(D33="Purchased",G33,0) -> 40
A34: 33 | B34: Drain Plug | C34: 3 | D34: Purchased | E34: 4 | F34: =G7*2 -> 90 | G34: =MAX(F34-E34,0) -> 86 | H34: =IF(D34="Manufactured",G34,0) -> 0 | I34: =IF(D34="Purchased",G34,0) -> 86
A35: 34 | B35: Hex Bolt M12 | C35: 3 | D35: Purchased | E35: 8 | F35: =G7*12 -> 540 | G35: =MAX(F35-E35,0) -> 532 | H35: =IF(D35="Manufactured",G35,0) -> 0 | I35: =IF(D35="Purchased",G35,0) -> 532
A36: 35 | B36: Hex Nut M12 | C36: 3 | D36: Purchased | E36: 8 | F36: =G7*12 -> 540 | G36: =MAX(F36-E36,0) -> 532 | H36: =IF(D36="Manufactured",G36,0) -> 0 | I36: =IF(D36="Purchased",G36,0) -> 532
A37: 36 | B37: Flat Washer | C37: 3 | D37: Purchased | E37: 8 | F37: =G7*12+G12*8+G16*6 -> 1170 | G37: =MAX(F37-E37,0) -> 1162 | H37: =IF(D37="Manufactured",G37,0) -> 0 | I37: =IF(D37="Purchased",G37,0) -> 1162
A38: 37 | B38: Spring Washer | C38: 3 | D38: Purchased | E38: 8 | F38: =G7*12 -> 540 | G38: =MAX(F38-E38,0) -> 532 | H38: =IF(D38="Manufactured",G38,0) -> 0 | I38: =IF(D38="Purchased",G38,0) -> 532
A39: 38 | B39: Pump Shaft | C39: 3 | D39: Purchased | E39: 2 | F39: =G8 -> 46 | G39: =MAX(F39-E39,0) -> 44 | H39: =IF(D39="Manufactured",G39,0) -> 0 | I39: =IF(D39="Purchased",G39,0) -> 44
A40: 39 | B40: Impeller | C40: 3 | D40: Purchased | E40: 3 | F40: =G8 -> 46 | G40: =MAX(F40-E40,0) -> 43 | H40: =IF(D40="Manufactured",G40,0) -> 0 | I40: =IF(D40="Purchased",G40,0) -> 43
...

Sheet Planned Production Orders
A1: production_order_id | B1: item_id | C1: item_name | D1: planned_quantity | E1: order_status
A2: {=_xlfn.SEQUENCE(ROWS(_xlfn.ANCHORARRAY(B2)))} -> 1 | B2: {=_xlfn._xlws.FILTER(MRP!A2:A86,MRP!H2:H86>0)} -> 1 | C2: {=_xlfn.XLOOKUP(_xlfn.ANCHORARRAY(B2),MRP!A2:A86,MRP!B2:B86)} -> Industrial Centrifugal Water Pump | D2: {=_xlfn.XLOOKUP(_xlfn.ANCHORARRAY(B2),MRP!A2:A86,MRP!H2:H86)} -> 46 | E2: {=IF(_xlfn.ANCHORARRAY(B2)<>"","Planned","")} -> Planned
A3: 2 | B3: 2 | C3: Pump Assembly | D3: 46 | E3: Planned
A4: 3 | B4: 3 | C4: Electric Motor Assembly | D4: 46 | E4: Planned
A5: 4 | B5: 4 | C5: Base Frame Assembly | D5: 46 | E5: Planned
A6: 5 | B6: 5 | C6: Packaging Assembly | D6: 46 | E6: Planned
A7: 6 | B7: 6 | C7: Casing Assembly | D7: 45 | E7: Planned
A8: 7 | B8: 7 | C8: Rotating Assembly | D8: 46 | E8: Planned
A9: 8 | B9: 8 | C9: Mechanical Seal Assembly | D9: 44 | E9: Planned
A10: 9 | B10: 11 | C10: Motor Housing Assembly | D10: 45 | E10: Planned
A11: 10 | B11: 12 | C11: Rotor Assembly | D11: 46 | E11: Planned
A12: 11 | B12: 13 | C12: Stator Assembly | D12: 45 | E12: Planned
A13: 12 | B13: 14 | C13: Cooling Fan Assembly | D13: 44 | E13: Planned
A14: 13 | B14: 15 | C14: Terminal Box Assembly | D14: 45 | E14: Planned

Sheet Planned Purchase Orders
A1: purchase_order_id | B1: item_id | C1: item_name | D1: supplier_id | E1: supplier_name | F1: planned_quantity | G1: order_status
A2: {=_xlfn.SEQUENCE(ROWS(_xlfn.ANCHORARRAY(B2)))} -> 1 | B2: {=_xlfn._xlws.FILTER(MRP!A2:A86,MRP!I2:I86>0)} -> 9 | C2: {=_xlfn.XLOOKUP(_xlfn.ANCHORARRAY(B2),tblItems[item_id],tblItems[item_name])} -> Suction Flange | D2: {=_xlfn.XLOOKUP(_xlfn.ANCHORARRAY(B2),tblItems[item_id],tblItems[supplier_id])} -> 3 | E2: {=_xlfn.XLOOKUP(_xlfn.ANCHORARRAY(D2),tblSuppliers[supplier_id],tblSuppliers[supplier_name])} -> L&T Valves | F2: {=_xlfn._xlws.FILTER(MRP!I2:I86,MRP!I2:I86>0)} -> 42 | G2: {=IF(_xlfn.ANCHORARRAY(B2)<>"","Planned","")} -> Planned
A3: 2 | B3: 10 | C3: Discharge Flange | D3: 3 | E3: L&T Valves | F3: 43 | G3: Planned
A4: 3 | B4: 16 | C4: Base Plate | D4: 4 | E4: Tata Steel Processing | F4: 42 | G4: Planned
A5: 4 | B5: 17 | C5: Mounting Feet | D5: 4 | E5: Tata Steel Processing | F5: 87 | G5: Planned
A6: 5 | B6: 18 | C6: Coupling Guard | D6: 4 | E6: Tata Steel Processing | F6: 43 | G6: Planned
A7: 6 | B7: 19 | C7: Anti Vibration Pads | D7: 2 | E7: Trelleborg Sealing Solutions | F7: 180 | G7: Planned
A8: 7 | B8: 20 | C8: Anchor Bolts | D8: 8 | E8: Fasteners India Pvt. Ltd. | F8: 176 | G8: Planned
A9: 8 | B9: 21 | C9: Anchor Nuts | D9: 8 | E9: Fasteners India Pvt. Ltd. | F9: 176 | G9: Planned
A10: 9 | B10: 22 | C10: Flat Washers | D10: 8 | E10: Fasteners India Pvt. Ltd. | F10: 176 | G10: Planned
A11: 10 | B11: 23 | C11: Carton Box | D11: 9 | E11: Packwell Packaging | F11: 42 | G11: Planned
A12: 11 | B12: 24 | C12: Foam Inserts | D12: 9 | E12: Packwell Packaging | F12: 87 | G12: Planned
A13: 12 | B13: 25 | C13: Plastic Bag | D13: 9 | E13: Packwell Packaging | F13: 42 | G13: Planned
A14: 13 | B14: 26 | C14: User Manual | D14: 9 | E14: Packwell Packaging | F14: 38 | G14: Planned
... A73: 72 | B73: 85 | C73: Cable Clamp | D73: 10 | E73: C&S Electric | F73: 86 | G73: Planned
